<mujoco model="go2">
  <compiler angle="radian" autolimits="true"/>

  <option cone="elliptic" impratio="100"/>

  <default>
    <default class="go2">
      <geom friction="0.6" margin="0.001" condim="1"/>
      <joint axis="0 1 0" damping="2" armature="0.01" frictionloss="0.2"/>
      <motor ctrlrange="-23.7 23.7"/>
      <default class="abduction">
        <joint axis="1 0 0" range="-1.0472 1.0472"/>
      </default>
      <default class="hip">
        <default class="front_hip">
          <joint range="-1.5708 3.4907"/>
        </default>
        <default class="back_hip">
          <joint range="-0.5236 4.5379"/>
        </default>
      </default>
      <default class="knee">
        <joint range="-2.7227 -0.83776"/>
        <motor ctrlrange="-45.43 45.43"/>
      </default>
      <default class="visual">
        <geom type="mesh" contype="0" conaffinity="0" group="2"/>
      </default>
      <default class="collision">
        <geom group="3"/>
        <default class="foot">
          <geom size="0.022" pos="-0.002 0 -0.213" priority="1" solimp="0.015 1 0.022" condim="6"
            friction="0.8 0.02 0.01"/>
        </default>
      </default>
    </default>
  </default>

  <asset>
    <material name="metal" rgba=".9 .95 .95 1"/>
    <material name="black" rgba="0 0 0 1"/>
    <material name="white" rgba="1 1 1 1"/>
    <material name="gray" rgba="0.671705 0.692426 0.774270 1"/>

    <mesh file="assets/base_0.obj"/>
    <mesh file="assets/base_1.obj"/>
    <mesh file="assets/base_2.obj"/>
    <mesh file="assets/base_3.obj"/>
    <mesh file="assets/base_4.obj"/>
    <mesh file="assets/hip_0.obj"/>
    <mesh file="assets/hip_1.obj"/>
    <mesh file="assets/thigh_0.obj"/>
    <mesh file="assets/thigh_1.obj"/>
    <mesh file="assets/thigh_mirror_0.obj"/>
    <mesh file="assets/thigh_mirror_1.obj"/>
    <mesh file="assets/calf_0.obj"/>
    <mesh file="assets/calf_1.obj"/>
    <mesh file="assets/calf_mirror_0.obj"/>
    <mesh file="assets/calf_mirror_1.obj"/>
    <mesh file="assets/foot.obj"/>

    <material name="mat_huashan" rgba="0.8 0.8 0.8 1" />
    <mesh file="assets/huashan/part_0.obj" name="huashan_0"   scale="10 10 5" />
    <mesh file="assets/huashan/part_1.obj" name="huashan_1"   scale="10 10 5" />
    <mesh file="assets/huashan/part_10.obj" name="huashan_2"  scale="10 10 5" />
    <mesh file="assets/huashan/part_11.obj" name="huashan_3"  scale="10 10 5" />
    <mesh file="assets/huashan/part_12.obj" name="huashan_4"  scale="10 10 5" />
    <mesh file="assets/huashan/part_13.obj" name="huashan_5"  scale="10 10 5" />
    <mesh file="assets/huashan/part_14.obj" name="huashan_6"  scale="10 10 5" />
    <mesh file="assets/huashan/part_15.obj" name="huashan_7"  scale="10 10 5" />
    <mesh file="assets/huashan/part_16.obj" name="huashan_8"  scale="10 10 5" />
    <mesh file="assets/huashan/part_17.obj" name="huashan_9"  scale="10 10 5" />
    <mesh file="assets/huashan/part_18.obj" name="huashan_10" scale="10 10 5" />
    <mesh file="assets/huashan/part_19.obj" name="huashan_11" scale="10 10 5" />
    <mesh file="assets/huashan/part_2.obj" name="huashan_12"  scale="10 10 5" />
    <mesh file="assets/huashan/part_20.obj" name="huashan_13" scale="10 10 5" />
    <mesh file="assets/huashan/part_21.obj" name="huashan_14" scale="10 10 5" />
    <mesh file="assets/huashan/part_22.obj" name="huashan_15" scale="10 10 5" />
    <mesh file="assets/huashan/part_23.obj" name="huashan_16" scale="10 10 5" />
    <mesh file="assets/huashan/part_24.obj" name="huashan_17" scale="10 10 5" />
    <mesh file="assets/huashan/part_25.obj" name="huashan_18" scale="10 10 5" />
    <mesh file="assets/huashan/part_26.obj" name="huashan_19" scale="10 10 5" />
    <mesh file="assets/huashan/part_27.obj" name="huashan_20" scale="10 10 5" />
    <mesh file="assets/huashan/part_28.obj" name="huashan_21" scale="10 10 5" />
    <mesh file="assets/huashan/part_29.obj" name="huashan_22" scale="10 10 5" />
    <mesh file="assets/huashan/part_3.obj" name="huashan_23"  scale="10 10 5" />
    <mesh file="assets/huashan/part_30.obj" name="huashan_24" scale="10 10 5" />
    <mesh file="assets/huashan/part_31.obj" name="huashan_25" scale="10 10 5" />
    <mesh file="assets/huashan/part_32.obj" name="huashan_26" scale="10 10 5" />
    <mesh file="assets/huashan/part_33.obj" name="huashan_27" scale="10 10 5" />
    <mesh file="assets/huashan/part_34.obj" name="huashan_28" scale="10 10 5" />
    <mesh file="assets/huashan/part_35.obj" name="huashan_29" scale="10 10 5" />
    <mesh file="assets/huashan/part_36.obj" name="huashan_30" scale="10 10 5" />
    <mesh file="assets/huashan/part_37.obj" name="huashan_31" scale="10 10 5" />
    <mesh file="assets/huashan/part_38.obj" name="huashan_32" scale="10 10 5" />
    <mesh file="assets/huashan/part_39.obj" name="huashan_33" scale="10 10 5" />
    <mesh file="assets/huashan/part_4.obj" name="huashan_34"  scale="10 10 5" />
    <mesh file="assets/huashan/part_40.obj" name="huashan_35" scale="10 10 5" />
    <mesh file="assets/huashan/part_41.obj" name="huashan_36" scale="10 10 5" />
    <mesh file="assets/huashan/part_42.obj" name="huashan_37" scale="10 10 5" />
    <mesh file="assets/huashan/part_5.obj" name="huashan_38"  scale="10 10 5" />
    <mesh file="assets/huashan/part_6.obj" name="huashan_39"  scale="10 10 5" />
    <mesh file="assets/huashan/part_7.obj" name="huashan_40"  scale="10 10 5" />
    <mesh file="assets/huashan/part_8.obj" name="huashan_41"  scale="10 10 5" />
    <mesh file="assets/huashan/part_9.obj" name="huashan_42"  scale="10 10 5" />

    <texture type="skybox" builtin="gradient" rgb1="0.3 0.5 0.7" rgb2="0 0 0" width="512" height="3072"/>
    <texture type="2d" name="groundplane" builtin="checker" mark="edge" rgb1="0.2 0.3 0.4" rgb2="0.1 0.2 0.3"
      markrgb="0.8 0.8 0.8" width="300" height="300"/>
    <material name="groundplane" texture="groundplane" texuniform="true" texrepeat="5 5" reflectance="0.2"/>

  </asset>

  <worldbody>
    <light pos="0 0 1.5" dir="0 0 -1" directional="true"/>
    <geom name="floor" size="0 0 0.05" type="plane" material="groundplane"/>

    <!-- huashan -->
    <body name="mesh_huashan" pos="6 -1 2.5" euler="0 0 1.5708">
        <geom type="mesh" mesh="huashan_0" material="mat_huashan" />
        <geom type="mesh" mesh="huashan_1" material="mat_huashan" />
        <geom type="mesh" mesh="huashan_2" material="mat_huashan" />
        <geom type="mesh" mesh="huashan_3" material="mat_huashan" />
        <geom type="mesh" mesh="huashan_4" material="mat_huashan" />
        <geom type="mesh" mesh="huashan_5" material="mat_huashan" />
        <geom type="mesh" mesh="huashan_6" material="mat_huashan" />
        <geom type="mesh" mesh="huashan_7" material="mat_huashan" />
        <geom type="mesh" mesh="huashan_8" material="mat_huashan" />
        <geom type="mesh" mesh="huashan_9" material="mat_huashan" />
        <geom type="mesh" mesh="huashan_10" material="mat_huashan" />
        <geom type="mesh" mesh="huashan_11" material="mat_huashan" />
        <geom type="mesh" mesh="huashan_12" material="mat_huashan" />
        <geom type="mesh" mesh="huashan_13" material="mat_huashan" />
        <geom type="mesh" mesh="huashan_14" material="mat_huashan" />
        <geom type="mesh" mesh="huashan_15" material="mat_huashan" />
        <geom type="mesh" mesh="huashan_16" material="mat_huashan" />
        <geom type="mesh" mesh="huashan_17" material="mat_huashan" />
        <geom type="mesh" mesh="huashan_18" material="mat_huashan" />
        <geom type="mesh" mesh="huashan_19" material="mat_huashan" />
        <geom type="mesh" mesh="huashan_20" material="mat_huashan" />
        <geom type="mesh" mesh="huashan_21" material="mat_huashan" />
        <geom type="mesh" mesh="huashan_22" material="mat_huashan" />
        <geom type="mesh" mesh="huashan_23" material="mat_huashan" />
        <geom type="mesh" mesh="huashan_24" material="mat_huashan" />
        <geom type="mesh" mesh="huashan_25" material="mat_huashan" />
        <geom type="mesh" mesh="huashan_26" material="mat_huashan" />
        <geom type="mesh" mesh="huashan_27" material="mat_huashan" />
        <geom type="mesh" mesh="huashan_28" material="mat_huashan" />
        <geom type="mesh" mesh="huashan_29" material="mat_huashan" />
        <geom type="mesh" mesh="huashan_30" material="mat_huashan" />
        <geom type="mesh" mesh="huashan_31" material="mat_huashan" />
        <geom type="mesh" mesh="huashan_32" material="mat_huashan" />
        <geom type="mesh" mesh="huashan_33" material="mat_huashan" />
        <geom type="mesh" mesh="huashan_34" material="mat_huashan" />
        <geom type="mesh" mesh="huashan_35" material="mat_huashan" />
        <geom type="mesh" mesh="huashan_36" material="mat_huashan" />
        <geom type="mesh" mesh="huashan_37" material="mat_huashan" />
        <geom type="mesh" mesh="huashan_38" material="mat_huashan" />
        <geom type="mesh" mesh="huashan_39" material="mat_huashan" />
        <geom type="mesh" mesh="huashan_40" material="mat_huashan" />
        <geom type="mesh" mesh="huashan_41" material="mat_huashan" />
        <geom type="mesh" mesh="huashan_42" material="mat_huashan" />
        </body>


    <body name="base" pos="0 0 0.445" childclass="go2">
      <inertial pos="0.021112 0 -0.005366" quat="-0.000543471 0.713435 -0.00173769 0.700719" mass="6.921"
        diaginertia="0.107027 0.0980771 0.0244531"/>
      <freejoint/>
      <geom mesh="base_0" material="black" class="visual"/>
      <geom mesh="base_1" material="black" class="visual"/>
      <geom mesh="base_2" material="black" class="visual"/>
      <geom mesh="base_3" material="white" class="visual"/>
      <geom mesh="base_4" material="gray" class="visual"/>
      <geom size="0.1881 0.04675 0.057" type="box" class="collision"/>
      <geom size="0.05 0.045" pos="0.285 0 0.01" type="cylinder" class="collision"/>
      <geom size="0.047" pos="0.293 0 -0.06" class="collision"/>
      <site name="imu" pos="-0.02557 0 0.04232"/>
      <body name="FL_hip" pos="0.1934 0.0465 0">
        <inertial pos="-0.0054 0.00194 -0.000105" quat="0.497014 0.499245 0.505462 0.498237" mass="0.678"
          diaginertia="0.00088403 0.000596003 0.000479967"/>
        <joint name="FL_hip_joint" class="abduction"/>
        <geom mesh="hip_0" material="metal" class="visual"/>
        <geom mesh="hip_1" material="gray" class="visual"/>
        <geom size="0.046 0.02" pos="0 0.08 0" quat="1 1 0 0" type="cylinder" class="collision"/>
        <body name="FL_thigh" pos="0 0.0955 0">
          <inertial pos="-0.00374 -0.0223 -0.0327" quat="0.829533 0.0847635 -0.0200632 0.551623" mass="1.152"
            diaginertia="0.00594973 0.00584149 0.000878787"/>
          <joint name="FL_thigh_joint" class="front_hip"/>
          <geom mesh="thigh_0" material="metal" class="visual"/>
          <geom mesh="thigh_1" material="gray" class="visual"/>
          <geom size="0.1065 0.01225 0.017" pos="0 0 -0.1065" quat="0.707107 0 0.707107 0" type="box" class="collision"/>
          <body name="FL_calf" pos="0 0 -0.213">
            <inertial pos="0.00629595 -0.000622121 -0.141417" quat="0.710672 0.00154099 -0.00450087 0.703508"
              mass="0.241352" diaginertia="0.0014901 0.00146356 5.31397e-05"/>
            <joint name="FL_calf_joint" class="knee"/>
            <geom mesh="calf_0" material="gray" class="visual"/>
            <geom mesh="calf_1" material="black" class="visual"/>
            <geom size="0.012 0.06" pos="0.008 0 -0.06" quat="0.994493 0 -0.104807 0" type="cylinder" class="collision"/>
            <geom size="0.011 0.0325" pos="0.02 0 -0.148" quat="0.999688 0 0.0249974 0" type="cylinder" class="collision"/>
            <geom pos="0 0 -0.213" mesh="foot" class="visual" material="black"/>
            <geom name="FL" class="foot"/>
          </body>
        </body>
      </body>
      <body name="FR_hip" pos="0.1934 -0.0465 0">
        <inertial pos="-0.0054 -0.00194 -0.000105" quat="0.498237 0.505462 0.499245 0.497014" mass="0.678"
          diaginertia="0.00088403 0.000596003 0.000479967"/>
        <joint name="FR_hip_joint" class="abduction"/>
        <geom mesh="hip_0" material="metal" class="visual" quat="4.63268e-05 1 0 0"/>
        <geom mesh="hip_1" material="gray" class="visual" quat="4.63268e-05 1 0 0"/>
        <geom size="0.046 0.02" pos="0 -0.08 0" quat="0.707107 0.707107 0 0" type="cylinder" class="collision"/>
        <body name="FR_thigh" pos="0 -0.0955 0">
          <inertial pos="-0.00374 0.0223 -0.0327" quat="0.551623 -0.0200632 0.0847635 0.829533" mass="1.152"
            diaginertia="0.00594973 0.00584149 0.000878787"/>
          <joint name="FR_thigh_joint" class="front_hip"/>
          <geom mesh="thigh_mirror_0" material="metal" class="visual"/>
          <geom mesh="thigh_mirror_1" material="gray" class="visual"/>
          <geom size="0.1065 0.01225 0.017" pos="0 0 -0.1065" quat="0.707107 0 0.707107 0" type="box" class="collision"/>
          <body name="FR_calf" pos="0 0 -0.213">
            <inertial pos="0.00629595 0.000622121 -0.141417" quat="0.703508 -0.00450087 0.00154099 0.710672"
              mass="0.241352" diaginertia="0.0014901 0.00146356 5.31397e-05"/>
            <joint name="FR_calf_joint" class="knee"/>
            <geom mesh="calf_mirror_0" material="gray" class="visual"/>
            <geom mesh="calf_mirror_1" material="black" class="visual"/>
            <geom size="0.013 0.06" pos="0.01 0 -0.06" quat="0.995004 0 -0.0998334 0" type="cylinder" class="collision"/>
            <geom size="0.011 0.0325" pos="0.02 0 -0.148" quat="0.999688 0 0.0249974 0" type="cylinder" class="collision"/>
            <geom pos="0 0 -0.213" mesh="foot" class="visual" material="black"/>
            <geom name="FR" class="foot"/>
          </body>
        </body>
      </body>
      <body name="RL_hip" pos="-0.1934 0.0465 0">
        <inertial pos="0.0054 0.00194 -0.000105" quat="0.505462 0.498237 0.497014 0.499245" mass="0.678"
          diaginertia="0.00088403 0.000596003 0.000479967"/>
        <joint name="RL_hip_joint" class="abduction"/>
        <geom mesh="hip_0" material="metal" class="visual" quat="4.63268e-05 0 1 0"/>
        <geom mesh="hip_1" material="gray" class="visual" quat="4.63268e-05 0 1 0"/>
        <geom size="0.046 0.02" pos="0 0.08 0" quat="0.707107 0.707107 0 0" type="cylinder" class="collision"/>
        <body name="RL_thigh" pos="0 0.0955 0">
          <inertial pos="-0.00374 -0.0223 -0.0327" quat="0.829533 0.0847635 -0.0200632 0.551623" mass="1.152"
            diaginertia="0.00594973 0.00584149 0.000878787"/>
          <joint name="RL_thigh_joint" class="back_hip"/>
          <geom mesh="thigh_0" material="metal" class="visual"/>
          <geom mesh="thigh_1" material="gray" class="visual"/>
          <geom size="0.1065 0.01225 0.017" pos="0 0 -0.1065" quat="0.707107 0 0.707107 0" type="box" class="collision"/>
          <body name="RL_calf" pos="0 0 -0.213">
            <inertial pos="0.00629595 -0.000622121 -0.141417" quat="0.710672 0.00154099 -0.00450087 0.703508"
              mass="0.241352" diaginertia="0.0014901 0.00146356 5.31397e-05"/>
            <joint name="RL_calf_joint" class="knee"/>
            <geom mesh="calf_0" material="gray" class="visual"/>
            <geom mesh="calf_1" material="black" class="visual"/>
            <geom size="0.013 0.06" pos="0.01 0 -0.06" quat="0.995004 0 -0.0998334 0" type="cylinder" class="collision"/>
            <geom size="0.011 0.0325" pos="0.02 0 -0.148" quat="0.999688 0 0.0249974 0" type="cylinder" class="collision"/>
            <geom pos="0 0 -0.213" mesh="foot" class="visual" material="black"/>
            <geom name="RL" class="foot"/>
          </body>
        </body>
      </body>
      <body name="RR_hip" pos="-0.1934 -0.0465 0">
        <inertial pos="0.0054 -0.00194 -0.000105" quat="0.499245 0.497014 0.498237 0.505462" mass="0.678"
          diaginertia="0.00088403 0.000596003 0.000479967"/>
        <joint name="RR_hip_joint" class="abduction"/>
        <geom mesh="hip_0" material="metal" class="visual" quat="2.14617e-09 4.63268e-05 4.63268e-05 -1"/>
        <geom mesh="hip_1" material="gray" class="visual" quat="2.14617e-09 4.63268e-05 4.63268e-05 -1"/>
        <geom size="0.046 0.02" pos="0 -0.08 0" quat="0.707107 0.707107 0 0" type="cylinder" class="collision"/>
        <body name="RR_thigh" pos="0 -0.0955 0">
          <inertial pos="-0.00374 0.0223 -0.0327" quat="0.551623 -0.0200632 0.0847635 0.829533" mass="1.152"
            diaginertia="0.00594973 0.00584149 0.000878787"/>
          <joint name="RR_thigh_joint" class="back_hip"/>
          <geom mesh="thigh_mirror_0" material="metal" class="visual"/>
          <geom mesh="thigh_mirror_1" material="gray" class="visual"/>
          <geom size="0.1065 0.01225 0.017" pos="0 0 -0.1065" quat="0.707107 0 0.707107 0" type="box" class="collision"/>
          <body name="RR_calf" pos="0 0 -0.213">
            <inertial pos="0.00629595 0.000622121 -0.141417" quat="0.703508 -0.00450087 0.00154099 0.710672"
              mass="0.241352" diaginertia="0.0014901 0.00146356 5.31397e-05"/>
            <joint name="RR_calf_joint" class="knee"/>
            <geom mesh="calf_mirror_0" material="gray" class="visual"/>
            <geom mesh="calf_mirror_1" material="black" class="visual"/>
            <geom size="0.013 0.06" pos="0.01 0 -0.06" quat="0.995004 0 -0.0998334 0" type="cylinder" class="collision"/>
            <geom size="0.011 0.0325" pos="0.02 0 -0.148" quat="0.999688 0 0.0249974 0" type="cylinder" class="collision"/>
            <geom pos="0 0 -0.213" mesh="foot" class="visual" material="black"/>
            <geom name="RR" class="foot"/>
          </body>
        </body>
      </body>
    </body>
  </worldbody>

  <actuator>
    <motor class="abduction" name="FL_hip" joint="FL_hip_joint"/>
    <motor class="hip" name="FL_thigh" joint="FL_thigh_joint"/>
    <motor class="knee" name="FL_calf" joint="FL_calf_joint"/>
    <motor class="abduction" name="FR_hip" joint="FR_hip_joint"/>
    <motor class="hip" name="FR_thigh" joint="FR_thigh_joint"/>
    <motor class="knee" name="FR_calf" joint="FR_calf_joint"/>
    <motor class="abduction" name="RL_hip" joint="RL_hip_joint"/>
    <motor class="hip" name="RL_thigh" joint="RL_thigh_joint"/>
    <motor class="knee" name="RL_calf" joint="RL_calf_joint"/>
    <motor class="abduction" name="RR_hip" joint="RR_hip_joint"/>
    <motor class="hip" name="RR_thigh" joint="RR_thigh_joint"/>
    <motor class="knee" name="RR_calf" joint="RR_calf_joint"/>
  </actuator>

  <keyframe>
    <key name="home" qpos="0 0 0.27 1 0 0 0 0 0.9 -1.8 0 0.9 -1.8 0 0.9 -1.8 0 0.9 -1.8"
      ctrl="0 0.9 -1.8 0 0.9 -1.8 0 0.9 -1.8 0 0.9 -1.8"/>
  </keyframe>
</mujoco>
